[2024-06-01T16:07:15.562+0000] {task_context_logger.py:104} ERROR - Executor reports task instance <TaskInstance: etl_pipeline.extract_csv_data scheduled__2023-01-12T00:00:00+00:00 [queued]> finished (failed) although the task says it's queued. (Info: None) Was the task killed externally?
