[2024-06-01T16:06:28.018+0000] {task_context_logger.py:104} ERROR - Executor reports task instance <TaskInstance: etl_pipeline.extract_csv_data manual__2024-06-01T16:05:31.132602+00:00 [queued]> finished (failed) although the task says it's queued. (Info: None) Was the task killed externally?
